Workbook

Sheet Assumptions
A1: 📋 MODEL ASSUMPTIONS — Odoo SaaS (West Africa)
A3: DIRECT CUSTOMER PLANS
A4: Plan | B4: Price (FCFA/30d) | C4: RAM (GB)
A5: Starter | B5: 10000 | C5: 1.5
A6: Pro | B6: 20000 | C6: 2
A7: Enterprise | B7: 50000 | C7: 6
A9: CREDIT SYSTEM
A10: Parameter | B10: Value
A11: Credits per 10,000 FCFA | B11: 10
A12: Starter credits / 30 days | B12: 10
A13: Pro credits / 30 days | B13: 20
A14: Enterprise credits / 30 days | B14: 50
A15: n8n deduction interval (minutes) | B15: 15
A17: RESELLER BUNDLES
A18: Bundle | B18: Instances | C18: Expiry (days)
A19: Small | B19: 10 | C19: 30
A20: Medium | B20: 20 | C20: 45
A21: Large | B21: 40 | C21: 60
A23: RESELLER DISCOUNTS
A24: Bundle | B24: Discount % | C24: Grace Period (days)
A25: Small | B25: 0.2 | C25: 5
A26: Medium | B26: 0.2 | C26: 5
A27: Large | B27: 0.35 | C27: 10
A29: CUSTOMER MIX
A30: Segment | B30: Split % | C30: Notes
A31: Direct / Reseller split (direct %) | B31: 0.5 | C31: 50% direct, 50% reseller
A32: Starter share of direct | B32: 0.7
A33: Pro share of direct | B33: 0.2
A34: Enterprise share of direct | B34: 0.1
A35: Reseller Small share | B35: 0.5
A36: Reseller Medium share | B36: 0.35
A37: Reseller Large share | B37: 0.15
A38: Expired credits estimate | B38: 0.2 | C38: Pure profit, no infra cost
A40: INFRASTRUCTURE (HETZNER)
A41: Item | B41: Cost (FCFA/month) | C41: Notes
A42: CX32 — Management node (1x) | B42: 4800 | C42: Traefik, AWX, n8n, Supabase
A43: CX52 — Customer node (per node) | B43: 16800 | C43: 32GB RAM, ~16 instances @ 1.8GB avg
A44: Usable RAM per CX52 (GB) | B44: 30 | C44: 32GB minus OS overhead
A45: Avg RAM per instance (GB) | B45: 1.8 | C45: Weighted avg across plan mix
A47: SALES TEAM
...

Sheet P&L
A1: 📊 P&L MODEL — Odoo SaaS (West Africa)
A2: Line Item | B2: 40 Accounts | C2: 100 Accounts | D2: 200 Accounts
A4: REVENUE
A5: Direct customers | B5: =ROUND(40*Assumptions!B31,0) -> 20 | C5: =ROUND(100*Assumptions!B31,0) -> 50 | D5: =ROUND(200*Assumptions!B31,0) -> 100
A6: Starter revenue | B6: =ROUND(40*Assumptions!B31*Assumptions!B32,0)*Assumptions!B5 -> 140000 | C6: =ROUND(100*Assumptions!B31*Assumptions!B32,0)*Assumptions!B5 -> 350000 | D6: =ROUND(200*Assumptions!B31*Assumptions!B32,0)*Assumptions!B5 -> 700000
A7: Pro revenue | B7: =ROUND(40*Assumptions!B31*Assumptions!B33,0)*Assumptions!B6 -> 80000 | C7: =ROUND(100*Assumptions!B31*Assumptions!B33,0)*Assumptions!B6 -> 200000 | D7: =ROUND(200*Assumptions!B31*Assumptions!B33,0)*Assumptions!B6 -> 400000
A8: Enterprise revenue | B8: =ROUND(40*Assumptions!B31*Assumptions!B34,0)*Assumptions!B7 -> 100000 | C8: =ROUND(100*Assumptions!B31*Assumptions!B34,0)*Assumptions!B7 -> 250000 | D8: =ROUND(200*Assumptions!B31*Assumptions!B34,0)*Assumptions!B7 -> 500000
A9: Total direct revenue | B9: =SUM(B6:B8) -> 320000 | C9: =SUM(C6:C8) -> 800000 | D9: =SUM(D6:D8) -> 1600000
A10: Reseller instances (50% of accounts) | B10: =ROUND(40*(1-Assumptions!B31),0) -> 20 | C10: =ROUND(100*(1-Assumptions!B31),0) -> 50 | D10: =ROUND(200*(1-Assumptions!B31),0) -> 100
A11: Reseller Starter revenue | B11: =ROUND(40*(1-Assumptions!B31)*Assumptions!B32,0)*Assumptions!B5*(1-(Assumptions!B35*Assumptions!B25+Assumptions!B36*Assumptions!B26+Assumptions!B37*Assumptions!B27)) -> 108850 | C11: =ROUND(100*(1-Assumptions!B31)*Assumptions!B32,0)*Assumptions!B5*(1-(Assumptions!B35*Assumptions!B25+Assumptions!B36*Assumptions!B26+Assumptions!B37*Assumptions!B27)) -> 272125 | D11: =ROUND(200*(1-Assumptions!B31)*Assumptions!B32,0)*Assumptions!B5*(1-(Assumptions!B35*Assumptions!B25+Assumptions!B36*Assumptions!B26+Assumptions!B37*Assumptions!B27)) -> 544250
A12: Reseller Pro revenue | B12: =ROUND(40*(1-Assumptions!B31)*Assumptions!B33,0)*Assumptions!B6*(1-(Assumptions!B35*Assumptions!B25+Assumptions!B36*Assumptions!B26+Assumptions!B37*Assumptions!B27)) -> 62200 | C12: =ROUND(100*(1-Assumptions!B31)*Assumptions!B33,0)*Assumptions!B6*(1-(Assumptions!B35*Assumptions!B25+Assumptions!B36*Assumptions!B26+Assumptions!B37*Assumptions!B27)) -> 155500 | D12: =ROUND(200*(1-Assumptions!B31)*Assumptions!B33,0)*Assumptions!B6*(1-(Assumptions!B35*Assumptions!B25+Assumptions!B36*Assumptions!B26+Assumptions!B37*Assumptions!B27)) -> 311000
A13: Reseller Enterprise revenue | B13: =ROUND(40*(1-Assumptions!B31)*Assumptions!B34,0)*Assumptions!B7*(1-(Assumptions!B35*Assumptions!B25+Assumptions!B36*Assumptions!B26+Assumptions!B37*Assumptions!B27)) -> 77750 | C13: =ROUND(100*(1-Assumptions!B31)*Assumptions!B34,0)*Assumptions!B7*(1-(Assumptions!B35*Assumptions!B25+Assumptions!B36*Assumptions!B26+Assumptions!B37*Assumptions!B27)) -> 194375 | D13: =ROUND(200*(1-Assumptions!B31)*Assumptions!B34,0)*Assumptions!B7*(1-(Assumptions!B35*Assumptions!B25+Assumptions!B36*Assumptions!B26+Assumptions!B37*Assumptions!B27)) -> 388750
A14: Total reseller revenue | B14: =SUM(B11:B13) -> 248800 | C14: =SUM(C11:C13) -> 622000 | D14: =SUM(D11:D13) -> 1244000
A15: Expired credits (pure profit) | B15: =B14*Assumptions!B38 -> 49760 | C15: =C14*Assumptions!B38 -> 124400 | D15: =D14*Assumptions!B38 -> 248800
A16: TOTAL REVENUE | B16: =B9+B14+B15 -> 618560 | C16: =C9+C14+C15 -> 1546400 | D16: =D9+D14+D15 -> 3092800
A18: COSTS
A19: Hetzner CX32 — management node (fixed) | B19: =Assumptions!B42 -> 4800 | C19: =Assumptions!B42 -> 4800 | D19: =Assumptions!B42 -> 4800
A20: Hetzner CX52 — customer nodes | B20: =CEILING(40*Assumptions!B45/Assumptions!B44,1)*Assumptions!B43 -> 50400 | C20: =CEILING(100*Assumptions!B45/Assumptions!B44,1)*Assumptions!B43 -> 100800 | D20: =CEILING(200*Assumptions!B45/Assumptions!B44,1)*Assumptions!B43 -> 201600
A21: Ops / your time | B21: 75000 | C21: 150000 | D21: 250000
A22: Sales team — base salary (2 consultants) | B22: =Assumptions!B49*Assumptions!B50 -> 200000 | C22: =Assumptions!B49*Assumptions!B50 -> 200000 | D22: =Assumptions!B49*Assumptions!B50 -> 200000
A23: Sales team — acquisition bonus | B23: =ROUND(40*0.1,0)*(Assumptions!B32*Assumptions!B5+Assumptions!B33*Assumptions!B6+Assumptions!B34*Assumptions!B7)*Assumptions!B52 -> 6400 | C23: =ROUND(100*0.1,0)*(Assumptions!B32*Assumptions!B5+Assumptions!B33*Assumptions!B6+Assumptions!B34*Assumptions!B7)*Assumptions!B52 -> 16000 | D23: =ROUND(200*0.1,0)*(Assumptions!B32*Assumptions!B5+Assumptions!B33*Assumptions!B6+Assumptions!B34*Assumptions!B7)*Assumptions!B52 -> 32000
A24: Sales team — renewal commission | B24: =40*(Assumptions!B32*Assumptions!B5+Assumptions!B33*Assumptions!B6+Assumptions!B34*Assumptions!B7)*Assumptions!B53 -> 32000 | C24: =100*(Assumptions!B32*Assumptions!B5+Assumptions!B33*Assumptions!B6+Assumptions!B34*Assumptions!B7)*Assumptions!B53 -> 80000 | D24: =200*(Assumptions!B32*Assumptions!B5+Assumptions!B33*Assumptions!B6+Assumptions!B34*Assumptions!B7)*Assumptions!B53 -> 160000
A25: Support & misc (5% of revenue) | B25: =B16*0.05 -> 30928 | C25: =C16*0.05 -> 77320 | D25: =D16*0.05 -> 154640
A26: TOTAL COSTS | B26: =SUM(B19:B25) -> 399528 | C26: =SUM(C19:C25) -> 628920 | D26: =SUM(D19:D25) -> 1003040
A28: PROFIT SUMMARY
A29: NET PROFIT (FCFA) | B29: =B16-B26 -> 219032 | C29: =C16-C26 -> 917480 | D29: =D16-D26 -> 2089760
A30: NET PROFIT (USD @ 600 FCFA) | B30: =B29/600 -> 365.05333 | C30: =C29/600 -> 1529.1333 | D30: =D29/600 -> 3482.9333
A31: MARGIN % | B31: =IF(B16=0,0,B29/B16) -> 0.35409984 | C31: =IF(C16=0,0,C29/C16) -> 0.59330057 | D31: =IF(D16=0,0,D29/D16) -> 0.67568546

Sheet Sales Performance
A1: 📈 SALES CONSULTANT PERFORMANCE COMPARISON — 6 Months
A2: Avg plan price: 16,000 FCFA | Acq bonus: 4,800 FCFA/customer (paid over 3 months) | Renewal: 800 FCFA/customer/month | Base: 100,000 FCFA (min 10 customers)
A4: UNDERPERFORMING — Barely above threshold — keeps base, low commission
A5: Month | B5: New Customers | C5: Portfolio | D5: Base Salary | E5: Base Lost | F5: Acq Bonus | G5: Renewal Comm | H5: Total Cost | I5: vs Performing | J5: Cumul. Cost | K5: Cumul. vs Performing
A6: Month 1 | B6: 2 | C6: 2 | D6: 0 | E6: 100000 | F6: 3200 | G6: 0 | H6: 3200 | I6: -3200 | J6: 3200 | K6: -3200
A7: Month 2 | B7: 2 | C7: 4 | D7: 0 | E7: 100000 | F7: 6400 | G7: 1600 | H7: 8000 | I7: -8000 | J7: 11200 | K7: -11200
A8: Month 3 | B8: 2 | C8: 6 | D8: 0 | E8: 100000 | F8: 9600 | G8: 3200 | H8: 12800 | I8: -112800 | J8: 24000 | K8: -124000
A9: Month 4 | B9: 2 | C9: 8 | D9: 0 | E9: 100000 | F9: 9600 | G9: 4800 | H9: 14400 | I9: -114400 | J9: 38400 | K9: -238400
A10: Month 5 | B10: 2 | C10: 10 | D10: 100000 | F10: 9600 | G10: 6400 | H10: 116000 | I10: -16000 | J10: 154400 | K10: -254400
A11: Month 6 | B11: 2 | C11: 12 | D11: 100000 | F11: 9600 | G11: 8000 | H11: 117600 | I11: -17600 | J11: 272000 | K11: -272000
A12: 6M TOTAL | B12: 12 | C12: 12 | D12: 200000 | E12: 400000 | F12: 48000 | G12: 24000 | H12: 272000 | I12: -272000 | J12: 272000 | K12: -272000
A14: PERFORMING — Solid performer — consistent, meets expectations
A15: Month | B15: New Customers | C15: Portfolio | D15: Base Salary | E15: Base Lost | F15: Acq Bonus | G15: Renewal Comm | H15: Total Cost | I15: vs Performing | J15: Cumul. Cost | K15: Cumul. vs Performing
A16: Month 1 | B16: 4 | C16: 4 | D16: 0 | E16: 100000 | F16: 6400 | G16: 0 | H16: 6400 | J16: 6400
A17: Month 2 | B17: 4 | C17: 8 | D17: 0 | E17: 100000 | F17: 12800 | G17: 3200 | H17: 16000 | J17: 22400
A18: Month 3 | B18: 4 | C18: 12 | D18: 100000 | F18: 19200 | G18: 6400 | H18: 125600 | J18: 148000
A19: Month 4 | B19: 4 | C19: 16 | D19: 100000 | F19: 19200 | G19: 9600 | H19: 128800 | J19: 276800
A20: Month 5 | B20: 4 | C20: 20 | D20: 100000 | F20: 19200 | G20: 12800 | H20: 132000 | J20: 408800
A21: Month 6 | B21: 4 | C21: 24 | D21: 100000 | F21: 19200 | G21: 16000 | H21: 135200 | J21: 544000
A22: 6M TOTAL | B22: 24 | C22: 24 | D22: 400000 | E22: 200000 | F22: 96000 | G22: 48000 | H22: 544000 | J22: 544000
A24: OVERPERFORMING — Doubles minimum target — high acquisition + renewal snowball
A25: Month | B25: New Customers | C25: Portfolio | D25: Base Salary | E25: Base Lost | F25: Acq Bonus | G25: Renewal Comm | H25: Total Cost | I25: vs Performing | J25: Cumul. Cost | K25: Cumul. vs Performing
A26: Month 1 | B26: 7 | C26: 7 | D26: 0 | E26: 100000 | F26: 11200 | G26: 0 | H26: 11200 | I26: 4800 | J26: 11200 | K26: 4800
A27: Month 2 | B27: 7 | C27: 14 | D27: 100000 | F27: 22400 | G27: 5600 | H27: 128000 | I27: 112000 | J27: 139200 | K27: 116800
A28: Month 3 | B28: 7 | C28: 21 | D28: 100000 | F28: 33600 | G28: 11200 | H28: 144800 | I28: 19200 | J28: 284000 | K28: 136000
A29: Month 4 | B29: 7 | C29: 28 | D29: 100000 | F29: 33600 | G29: 16800 | H29: 150400 | I29: 21600 | J29: 434400 | K29: 157600
A30: Month 5 | B30: 7 | C30: 35 | D30: 100000 | F30: 33600 | G30: 22400 | H30: 156000 | I30: 24000 | J30: 590400 | K30: 181600
A31: Month 6 | B31: 7 | C31: 42 | D31: 100000 | F31: 33600 | G31: 28000 | H31: 161600 | I31: 26400 | J31: 752000 | K31: 208000
A32: 6M TOTAL | B32: 42 | C32: 42 | D32: 500000 | E32: 100000 | F32: 168000 | G32: 84000 | H32: 752000 | I32: 208000 | J32: 752000 | K32: 208000
A34: UP & DOWN — Volatile — loses base salary in months where portfolio < 10
A35: Month | B35: New Customers | C35: Portfolio | D35: Base Salary | E35: Base Lost | F35: Acq Bonus | G35: Renewal Comm | H35: Total Cost | I35: vs Performing | J35: Cumul. Cost | K35: Cumul. vs Performing
A36: Month 1 | B36: 6 | C36: 6 | D36: 0 | E36: 100000 | F36: 9600 | G36: 0 | H36: 9600 | I36: 3200 | J36: 9600 | K36: 3200
A37: Month 2 | B37: 2 | C37: 8 | D37: 0 | E37: 100000 | F37: 12800 | G37: 4800 | H37: 17600 | I37: 1600 | J37: 27200 | K37: 4800
A38: Month 3 | B38: 8 | C38: 16 | D38: 100000 | F38: 25600 | G38: 6400 | H38: 132000 | I38: 6400 | J38: 159200 | K38: 11200
A39: Month 4 | B39: 1 | C39: 17 | D39: 100000 | F39: 17600 | G39: 12800 | H39: 130400 | I39: 1600 | J39: 289600 | K39: 12800
A40: Month 5 | B40: 7 | C40: 24 | D40: 100000 | F40: 25600 | G40: 13600 | H40: 139200 | I40: 7200 | J40: 428800 | K40: 20000
A41: Month 6 | B41: 2 | C41: 26 | D41: 100000 | F41: 16000 | G41: 19200 | H41: 135200 | J41: 564000 | K41: 20000
A42: 6M TOTAL | B42: 26 | C42: 26 | D42: 400000 | E42: 200000 | F42: 107200 | G42: 56800 | H42: 564000 | I42: 20000 | J42: 564000 | K42: 20000
A44: 📊 6-MONTH SUMMARY COMPARISON
A45: Profile | B45: Total New Customers | C45: Final Portfolio | D45: Total Cost (6M) | E45: vs Performing | F45: Avg Cost/Customer
...
